Workbook
Name new: OFFSET(Data!$A$1,0,0,COUNTA(Data!$A:$A),COUNTA(Data!$1:$1))
Name Slicer_Date: #N/A
Name Slicer_Financial_Quarter: #N/A
Name Slicer_Month_Name: #N/A
Name Slicer_Year: #N/A

Sheet Sheet2
A3: Total Transactions
A4: 9467 | C4: =GETPIVOTDATA("Transaction Details",$A$3) -> 9467
A8: Total Amount
A9: 94759149 | C9: =GETPIVOTDATA("Amount",$A$8) -> 94759149
A13: Total Credit
A14: 66254757 | C14: =GETPIVOTDATA("Credit Amount",$A$13) -> 66254757
A17: Total Debit
A18: 28504392 | C18: =GETPIVOTDATA("Debit Amount",$A$17) -> 28504392
A21: Average Transaction
A22: 10009.417 | C22: =GETPIVOTDATA("Amount",$A$21) -> 10009.417
A25: Highest Transaction
A26: 66327 | C26: =GETPIVOTDATA("Amount",$A$25) -> 66327
A30: Lowest Transaction
A31: 29 | C31: =GETPIVOTDATA("Amount",$A$30) -> 29
A39: Row Labels | B39: Sum of Amount
A40: Jan | B40: 8533418
A41: Feb | B41: 7530553
A42: Mar | B42: 8625665
A43: Apr | B43: 7174493
A44: May | B44: 7388642
A45: Jun | B45: 6749837
A46: Jul | B46: 7119662
A47: Aug | B47: 8736833
A48: Sep | B48: 8429276
A49: Oct | B49: 8375647
A50: Nov | B50: 7979473
A51: Dec | B51: 8115650
A52: Grand Total | B52: 94759149
A62: Row Labels | B62: Sum of Amount
A63: Sunday | B63: 13340460
A64: Monday | B64: 13048724
A65: Tuesday | B65: 14256585
A66: Wednesday | B66: 12886014
A67: Thursday | B67: 14103616
A68: Friday | B68: 13830555
A69: Saturday | B69: 13293195
A70: Grand Total | B70: 94759149
A86: Row Labels | B86: Sum of Amount
A87: Credit | B87: 66254757
A88: Debit | B88: 28504392
...

Sheet Dashboard

Sheet Data
A1: Date | B1: Time | C1: Transaction Details | D1: Transaction ID | E1: UTR | F1: Transaction Type | G1: Credit/debit instrument | H1: Amount | I1: Year | J1: Month Name | K1: Month Number | L1: Day Name | M1: Week Number | N1: Credit Amount | O1: Debit Amount | P1: Day | Q1: Times | R1: Time Group | S1: Days | T1: Category | U1: Hours | V1: Financial Quarter
A2: 44049 | B2: 10:05 | C2: Received from Family Member - Kumar | D2: T200806100500708200694 | E2: 826954970456 | F2: Credit | G2: XXXXXX3700 | H2: 13008 | I2: =YEAR(A2) -> 2020 | J2: =TEXT(A2,"mmmm") -> August | K2: =MONTH(A2) -> 8 | L2: =TEXT(A2,"dddd") -> Thursday | M2: =WEEKNUM(A2) -> 32 | N2: =IF(F2="Credit",H2,0) -> 13008 | O2: =IF(F2="Debit",H2,0) -> 0 | P2: =TEXT(A2,"d-mmm") -> 6-Aug | Q2: =TIMEVALUE(TRIM(CLEAN(SUBSTITUTE(B2,CHAR(34),"")))) -> 0.42013889 | R2: =IF(HOUR(Q2)<12,"Morning",IF(HOUR(Q2)<17,"Afternoon",IF(HOUR(Q2)<21,"Evening","Night"))) -> Morning | S2: =DAY(A2) -> 6 | T2: =IF(ISNUMBER(SEARCH("Recharge",C2)),"Recharge",IF(ISNUMBER(SEARCH("Petrol",C2)),"Fuel",IF(ISNUMBER(SEARCH("Restaurant",C2)),"Food",IF(ISNUMBER(SEARCH("Amazon",C2)),"Shopping",IF(ISNUMBER(SEARCH("Salary",C2)),"Salary",IF(ISNUMBER(SEARCH("Paid to",C2)),"UPI Transfer","Others")))))) -> Others | U2: =HOUR(Q2) -> 10 | V2: ="FY Q"&INT(MOD(MONTH(A2)-4,12)/3)+1 -> FY Q2
A3: 44049 | B3: 23:30 | C3: Received from Customer - ABC Traders | D3: T200806233000597786006 | E3: 634429950087 | F3: Credit | G3: XXXXXXXXXX0662 | H3: 8599 | I3: =YEAR(A3) -> 2020 | J3: =TEXT(A3,"mmmm") -> August | K3: =MONTH(A3) -> 8 | L3: =TEXT(A3,"dddd") -> Thursday | M3: =WEEKNUM(A3) -> 32 | N3: =IF(F3="Credit",H3,0) -> 8599 | O3: =IF(F3="Debit",H3,0) -> 0 | P3: =TEXT(A3,"d-mmm") -> 6-Aug | Q3: =TIMEVALUE(TRIM(CLEAN(SUBSTITUTE(B3,CHAR(34),"")))) -> 0.97916667 | R3: =IF(HOUR(Q3)<12,"Morning",IF(HOUR(Q3)<17,"Afternoon",IF(HOUR(Q3)<21,"Evening","Night"))) -> Night | S3: =DAY(A3) -> 6 | T3: =IF(ISNUMBER(SEARCH("Recharge",C3)),"Recharge",IF(ISNUMBER(SEARCH("Petrol",C3)),"Fuel",IF(ISNUMBER(SEARCH("Restaurant",C3)),"Food",IF(ISNUMBER(SEARCH("Amazon",C3)),"Shopping",IF(ISNUMBER(SEARCH("Salary",C3)),"Salary",IF(ISNUMBER(SEARCH("Paid to",C3)),"UPI Transfer","Others")))))) -> Others | U3: =HOUR(Q3) -> 23 | V3: ="FY Q"&INT(MOD(MONTH(A3)-4,12)/3)+1 -> FY Q2
A4: 44050 | B4: 11:30 | C4: Received from Customer - Sri Lakshmi Stores | D4: T200807113000864260112 | E4: 720437573492 | F4: Credit | G4: XXXXXX3700 | H4: 7846 | I4: =YEAR(A4) -> 2020 | J4: =TEXT(A4,"mmmm") -> August | K4: =MONTH(A4) -> 8 | L4: =TEXT(A4,"dddd") -> Friday | M4: =WEEKNUM(A4) -> 32 | N4: =IF(F4="Credit",H4,0) -> 7846 | O4: =IF(F4="Debit",H4,0) -> 0 | P4: =TEXT(A4,"d-mmm") -> 7-Aug | Q4: =TIMEVALUE(TRIM(CLEAN(SUBSTITUTE(B4,CHAR(34),"")))) -> 0.47916667 | R4: =IF(HOUR(Q4)<12,"Morning",IF(HOUR(Q4)<17,"Afternoon",IF(HOUR(Q4)<21,"Evening","Night"))) -> Morning | S4: =DAY(A4) -> 7 | T4: =IF(ISNUMBER(SEARCH("Recharge",C4)),"Recharge",IF(ISNUMBER(SEARCH("Petrol",C4)),"Fuel",IF(ISNUMBER(SEARCH("Restaurant",C4)),"Food",IF(ISNUMBER(SEARCH("Amazon",C4)),"Shopping",IF(ISNUMBER(SEARCH("Salary",C4)),"Salary",IF(ISNUMBER(SEARCH("Paid to",C4)),"UPI Transfer","Others")))))) -> Others | U4: =HOUR(Q4) -> 11 | V4: ="FY Q"&INT(MOD(MONTH(A4)-4,12)/3)+1 -> FY Q2
A5: 44050 | B5: 11:53 | C5: Received from Customer - Ramesh & Co | D5: T200807115300734061671 | E5: 307022960270 | F5: Credit | G5: XXXXXXXXXX0662 | H5: 7985 | I5: =YEAR(A5) -> 2020 | J5: =TEXT(A5,"mmmm") -> August | K5: =MONTH(A5) -> 8 | L5: =TEXT(A5,"dddd") -> Friday | M5: =WEEKNUM(A5) -> 32 | N5: =IF(F5="Credit",H5,0) -> 7985 | O5: =IF(F5="Debit",H5,0) -> 0 | P5: =TEXT(A5,"d-mmm") -> 7-Aug | Q5: =TIMEVALUE(TRIM(CLEAN(SUBSTITUTE(B5,CHAR(34),"")))) -> 0.49513889 | R5: =IF(HOUR(Q5)<12,"Morning",IF(HOUR(Q5)<17,"Afternoon",IF(HOUR(Q5)<21,"Evening","Night"))) -> Morning | S5: =DAY(A5) -> 7 | T5: =IF(ISNUMBER(SEARCH("Recharge",C5)),"Recharge",IF(ISNUMBER(SEARCH("Petrol",C5)),"Fuel",IF(ISNUMBER(SEARCH("Restaurant",C5)),"Food",IF(ISNUMBER(SEARCH("Amazon",C5)),"Shopping",IF(ISNUMBER(SEARCH("Salary",C5)),"Salary",IF(ISNUMBER(SEARCH("Paid to",C5)),"UPI Transfer","Others")))))) -> Others | U5: =HOUR(Q5) -> 11 | V5: ="FY Q"&INT(MOD(MONTH(A5)-4,12)/3)+1 -> FY Q2
A6: 44050 | B6: 12:42 | C6: Received from Local Customer | D6: T200807124200533217078 | E6: 768666203983 | F6: Credit | G6: XXXXXX3700 | H6: 14958 | I6: =YEAR(A6) -> 2020 | J6: =TEXT(A6,"mmmm") -> August | K6: =MONTH(A6) -> 8 | L6: =TEXT(A6,"dddd") -> Friday | M6: =WEEKNUM(A6) -> 32 | N6: =IF(F6="Credit",H6,0) -> 14958 | O6: =IF(F6="Debit",H6,0) -> 0 | P6: =TEXT(A6,"d-mmm") -> 7-Aug | Q6: =TIMEVALUE(TRIM(CLEAN(SUBSTITUTE(B6,CHAR(34),"")))) -> 0.52916667 | R6: =IF(HOUR(Q6)<12,"Morning",IF(HOUR(Q6)<17,"Afternoon",IF(HOUR(Q6)<21,"Evening","Night"))) -> Afternoon | S6: =DAY(A6) -> 7 | T6: =IF(ISNUMBER(SEARCH("Recharge",C6)),"Recharge",IF(ISNUMBER(SEARCH("Petrol",C6)),"Fuel",IF(ISNUMBER(SEARCH("Restaurant",C6)),"Food",IF(ISNUMBER(SEARCH("Amazon",C6)),"Shopping",IF(ISNUMBER(SEARCH("Salary",C6)),"Salary",IF(ISNUMBER(SEARCH("Paid to",C6)),"UPI Transfer","Others")))))) -> Others | U6: =HOUR(Q6) -> 12 | V6: ="FY Q"&INT(MOD(MONTH(A6)-4,12)/3)+1 -> FY Q2
A7: 44050 | B7: 23:43 | C7: Received from Family Member - Priya | D7: T200807234300753366478 | E7: 204215168097 | F7: Credit | G7: XXXXXX3700 | H7: 3486 | I7: =YEAR(A7) -> 2020 | J7: =TEXT(A7,"mmmm") -> August | K7: =MONTH(A7) -> 8 | L7: =TEXT(A7,"dddd") -> Friday | M7: =WEEKNUM(A7) -> 32 | N7: =IF(F7="Credit",H7,0) -> 3486 | O7: =IF(F7="Debit",H7,0) -> 0 | P7: =TEXT(A7,"d-mmm") -> 7-Aug | Q7: =TIMEVALUE(TRIM(CLEAN(SUBSTITUTE(B7,CHAR(34),"")))) -> 0.98819444 | R7: =IF(HOUR(Q7)<12,"Morning",IF(HOUR(Q7)<17,"Afternoon",IF(HOUR(Q7)<21,"Evening","Night"))) -> Night | S7: =DAY(A7) -> 7 | T7: =IF(ISNUMBER(SEARCH("Recharge",C7)),"Recharge",IF(ISNUMBER(SEARCH("Petrol",C7)),"Fuel",IF(ISNUMBER(SEARCH("Restaurant",C7)),"Food",IF(ISNUMBER(SEARCH("Amazon",C7)),"Shopping",IF(ISNUMBER(SEARCH("Salary",C7)),"Salary",IF(ISNUMBER(SEARCH("Paid to",C7)),"UPI Transfer","Others")))))) -> Others | U7: =HOUR(Q7) -> 23 | V7: ="FY Q"&INT(MOD(MONTH(A7)-4,12)/3)+1 -> FY Q2
A8: 44051 | B8: 11:50 | C8: Received from Customer - Anand Stores | D8: T200808115000108910348 | E8: 380079257052 | F8: Credit | G8: XXXXXX3700 | H8: 9452 | I8: =YEAR(A8) -> 2020 | J8: =TEXT(A8,"mmmm") -> August | K8: =MONTH(A8) -> 8 | L8: =TEXT(A8,"dddd") -> Saturday | M8: =WEEKNUM(A8) -> 32 | N8: =IF(F8="Credit",H8,0) -> 9452 | O8: =IF(F8="Debit",H8,0) -> 0 | P8: =TEXT(A8,"d-mmm") -> 8-Aug | Q8: =TIMEVALUE(TRIM(CLEAN(SUBSTITUTE(B8,CHAR(34),"")))) -> 0.49305556 | R8: =IF(HOUR(Q8)<12,"Morning",IF(HOUR(Q8)<17,"Afternoon",IF(HOUR(Q8)<21,"Evening","Night"))) -> Morning | S8: =DAY(A8) -> 8 | T8: =IF(ISNUMBER(SEARCH("Recharge",C8)),"Recharge",IF(ISNUMBER(SEARCH("Petrol",C8)),"Fuel",IF(ISNUMBER(SEARCH("Restaurant",C8)),"Food",IF(ISNUMBER(SEARCH("Amazon",C8)),"Shopping",IF(ISNUMBER(SEARCH("Salary",C8)),"Salary",IF(ISNUMBER(SEARCH("Paid to",C8)),"UPI Transfer","Others")))))) -> Others | U8: =HOUR(Q8) -> 11 | V8: ="FY Q"&INT(MOD(MONTH(A8)-4,12)/3)+1 -> FY Q2
A9: 44051 | B9: 17:36 | C9: Received from Family Member - Kumar | D9: T200808173600901157611 | E9: 972741244716 | F9: Credit | G9: XXXXXX3700 | H9: 8788 | I9: =YEAR(A9) -> 2020 | J9: =TEXT(A9,"mmmm") -> August | K9: =MONTH(A9) -> 8 | L9: =TEXT(A9,"dddd") -> Saturday | M9: =WEEKNUM(A9) -> 32 | N9: =IF(F9="Credit",H9,0) -> 8788 | O9: =IF(F9="Debit",H9,0) -> 0 | P9: =TEXT(A9,"d-mmm") -> 8-Aug | Q9: =TIMEVALUE(TRIM(CLEAN(SUBSTITUTE(B9,CHAR(34),"")))) -> 0.73333333 | R9: =IF(HOUR(Q9)<12,"Morning",IF(HOUR(Q9)<17,"Afternoon",IF(HOUR(Q9)<21,"Evening","Night"))) -> Evening | S9: =DAY(A9) -> 8 | T9: =IF(ISNUMBER(SEARCH("Recharge",C9)),"Recharge",IF(ISNUMBER(SEARCH("Petrol",C9)),"Fuel",IF(ISNUMBER(SEARCH("Restaurant",C9)),"Food",IF(ISNUMBER(SEARCH("Amazon",C9)),"Shopping",IF(ISNUMBER(SEARCH("Salary",C9)),"Salary",IF(ISNUMBER(SEARCH("Paid to",C9)),"UPI Transfer","Others")))))) -> Others | U9: =HOUR(Q9) -> 17 | V9: ="FY Q"&INT(MOD(MONTH(A9)-4,12)/3)+1 -> FY Q2
A10: 44051 | B10: 18:26 | C10: Received from Customer - Ramesh & Co | D10: T200808182600305991849 | E10: 980080391266 | F10: Credit | G10: XXXXXX3700 | H10: 1856 | I10: =YEAR(A10) -> 2020 | J10: =TEXT(A10,"mmmm") -> August | K10: =MONTH(A10) -> 8 | L10: =TEXT(A10,"dddd") -> Saturday | M10: =WEEKNUM(A10) -> 32 | N10: =IF(F10="Credit",H10,0) -> 1856 | O10: =IF(F10="Debit",H10,0) -> 0 | P10: =TEXT(A10,"d-mmm") -> 8-Aug | Q10: =TIMEVALUE(TRIM(CLEAN(SUBSTITUTE(B10,CHAR(34),"")))) -> 0.76805556 | R10: =IF(HOUR(Q10)<12,"Morning",IF(HOUR(Q10)<17,"Afternoon",IF(HOUR(Q10)<21,"Evening","Night"))) -> Evening | S10: =DAY(A10) -> 8 | T10: =IF(ISNUMBER(SEARCH("Recharge",C10)),"Recharge",IF(ISNUMBER(SEARCH("Petrol",C10)),"Fuel",IF(ISNUMBER(SEARCH("Restaurant",C10)),"Food",IF(ISNUMBER(SEARCH("Amazon",C10)),"Shopping",IF(ISNUMBER(SEARCH("Salary",C10)),"Salary",IF(ISNUMBER(SEARCH("Paid to",C10)),"UPI Transfer","Others")))))) -> Others | U10: =HOUR(Q10) -> 18 | V10: ="FY Q"&INT(MOD(MONTH(A10)-4,12)/3)+1 -> FY Q2
A11: 44051 | B11: 18:38 | C11: Paid to Other Merchant | D11: P200808183800771988680 | E11: 979650462626 | F11: Debit | G11: XXXXXX3700 | H11: 53361 | I11: =YEAR(A11) -> 2020 | J11: =TEXT(A11,"mmmm") -> August | K11: =MONTH(A11) -> 8 | L11: =TEXT(A11,"dddd") -> Saturday | M11: =WEEKNUM(A11) -> 32 | N11: =IF(F11="Credit",H11,0) -> 0 | O11: =IF(F11="Debit",H11,0) -> 53361 | P11: =TEXT(A11,"d-mmm") -> 8-Aug | Q11: =TIMEVALUE(TRIM(CLEAN(SUBSTITUTE(B11,CHAR(34),"")))) -> 0.77638889 | R11: =IF(HOUR(Q11)<12,"Morning",IF(HOUR(Q11)<17,"Afternoon",IF(HOUR(Q11)<21,"Evening","Night"))) -> Evening | S11: =DAY(A11) -> 8 | T11: =IF(ISNUMBER(SEARCH("Recharge",C11)),"Recharge",IF(ISNUMBER(SEARCH("Petrol",C11)),"Fuel",IF(ISNUMBER(SEARCH("Restaurant",C11)),"Food",IF(ISNUMBER(SEARCH("Amazon",C11)),"Shopping",IF(ISNUMBER(SEARCH("Salary",C11)),"Salary",IF(ISNUMBER(SEARCH("Paid to",C11)),"UPI Transfer","Others")))))) -> UPI Transfer | U11: =HOUR(Q11) -> 18 | V11: ="FY Q"&INT(MOD(MONTH(A11)-4,12)/3)+1 -> FY Q2
A12: 44051 | B12: 18:42 | C12: Received from Other UPI User | D12: T200808184200688585392 | E12: 78722594834 | F12: Credit | G12: XXXXXXXXXX0662 | H12: 9961 | I12: =YEAR(A12) -> 2020 | J12: =TEXT(A12,"mmmm") -> August | K12: =MONTH(A12) -> 8 | L12: =TEXT(A12,"dddd") -> Saturday | M12: =WEEKNUM(A12) -> 32 | N12: =IF(F12="Credit",H12,0) -> 9961 | O12: =IF(F12="Debit",H12,0) -> 0 | P12: =TEXT(A12,"d-mmm") -> 8-Aug | Q12: =TIMEVALUE(TRIM(CLEAN(SUBSTITUTE(B12,CHAR(34),"")))) -> 0.77916667 | R12: =IF(HOUR(Q12)<12,"Morning",IF(HOUR(Q12)<17,"Afternoon",IF(HOUR(Q12)<21,"Evening","Night"))) -> Evening | S12: =DAY(A12) -> 8 | T12: =IF(ISNUMBER(SEARCH("Recharge",C12)),"Recharge",IF(ISNUMBER(SEARCH("Petrol",C12)),"Fuel",IF(ISNUMBER(SEARCH("Restaurant",C12)),"Food",IF(ISNUMBER(SEARCH("Amazon",C12)),"Shopping",IF(ISNUMBER(SEARCH("Salary",C12)),"Salary",IF(ISNUMBER(SEARCH("Paid to",C12)),"UPI Transfer","Others")))))) -> Others | U12: =HOUR(Q12) -> 18 | V12: ="FY Q"&INT(MOD(MONTH(A12)-4,12)/3)+1 -> FY Q2
A13: 44051 | B13: 19:14 | C13: Paid to Bakery & Snacks | D13: P200808191400877644907 | E13: 703317848320 | F13: Debit | G13: XXXXXXXXXX0662 | H13: 3949 | I13: =YEAR(A13) -> 2020 | J13: =TEXT(A13,"mmmm") -> August | K13: =MONTH(A13) -> 8 | L13: =TEXT(A13,"dddd") -> Saturday | M13: =WEEKNUM(A13) -> 32 | N13: =IF(F13="Credit",H13,0) -> 0 | O13: =IF(F13="Debit",H13,0) -> 3949 | P13: =TEXT(A13,"d-mmm") -> 8-Aug | Q13: =TIMEVALUE(TRIM(CLEAN(SUBSTITUTE(B13,CHAR(34),"")))) -> 0.80138889 | R13: =IF(HOUR(Q13)<12,"Morning",IF(HOUR(Q13)<17,"Afternoon",IF(HOUR(Q13)<21,"Evening","Night"))) -> Evening | S13: =DAY(A13) -> 8 | T13: =IF(ISNUMBER(SEARCH("Recharge",C13)),"Recharge",IF(ISNUMBER(SEARCH("Petrol",C13)),"Fuel",IF(ISNUMBER(SEARCH("Restaurant",C13)),"Food",IF(ISNUMBER(SEARCH("Amazon",C13)),"Shopping",IF(ISNUMBER(SEARCH("Salary",C13)),"Salary",IF(ISNUMBER(SEARCH("Paid to",C13)),"UPI Transfer","Others")))))) -> UPI Transfer | U13: =HOUR(Q13) -> 19 | V13: ="FY Q"&INT(MOD(MONTH(A13)-4,12)/3)+1 -> FY Q2
... A9468: 46112 | B9468: 22:05 | C9468: Received from Customer - Ravi Enterprises | D9468: T260331220500231587031 | E9468: 751804892827 | F9468: Credit | G9468: XXXXXX3700 | H9468: 17761 | I9468: =YEAR(A9468) -> 2026 | J9468: =TEXT(A9468,"mmmm") -> March | K9468: =MONTH(A9468) -> 3 | L9468: =TEXT(A9468,"dddd") -> Tuesday | M9468: =WEEKNUM(A9468) -> 14 | N9468: =IF(F9468="Credit",H9468,0) -> 17761 | O9468: =IF(F9468="Debit",H9468,0) -> 0 | P9468: =TEXT(A9468,"d-mmm") -> 31-Mar | Q9468: =TIMEVALUE(TRIM(CLEAN(SUBSTITUTE(B9468,CHAR(34),"")))) -> 0.92013889 | R9468: =IF(HOUR(Q9468)<12,"Morning",IF(HOUR(Q9468)<17,"Afternoon",IF(HOUR(Q9468)<21,"Evening","Night"))) -> Night | S9468: =DAY(A9468) -> 31 | T9468: =IF(ISNUMBER(SEARCH("Recharge",C9468)),"Recharge",IF(ISNUMBER(SEARCH("Petrol",C9468)),"Fuel",IF(ISNUMBER(SEARCH("Restaurant",C9468)),"Food",IF(ISNUMBER(SEARCH("Amazon",C9468)),"Shopping",IF(ISNUMBER(SEARCH("Salary",C9468)),"Salary",IF(ISNUMBER(SEARCH("Paid to",C9468)),"UPI Transfer","Others")))))) -> Others | U9468: =HOUR(Q9468) -> 22 | V9468: ="FY Q"&INT(MOD(MONTH(A9468)-4,12)/3)+1 -> FY Q4
